<?xml version="1.0" ?>
<!-- =================================================================================== -->
<!-- |    This document was autogenerated by xacro from /home/gauss/projects/personal_ws/src/kr_50_r2500/kr_50_r2500_gazebo/urdf/kr_50_r2500.xacro | -->
<!-- |    EDITING THIS FILE BY HAND IS NOT RECOMMENDED                                 | -->
<!-- =================================================================================== -->
<robot name="kuka_robotiq">
    <!-- -350° -->
    <!--  360°/s -->
    <!-- Effort limit = V elocity limit * 5 -->
    <!-- <xacro:property name="joint1_eff_limit" value="13.74445" />
  <xacro:property name="joint2_eff_limit" value="12.40930" />
  <xacro:property name="joint3_eff_limit" value="13.74445" />
  <xacro:property name="joint4_eff_limit" value="19.63495" />
  <xacro:property name="joint5_eff_limit" value="19.63495" />
  <xacro:property name="joint6_eff_limit" value="28.27435" /> -->
    <link name="world" />
    <link name="base_link">
        <inertial>
            <origin rpy="0 0 0" xyz="-0.080585 0.00067592 0.086754" />
            <mass value="30.385" />
            <inertia ixx="0.38941" ixy="0.0047083" ixz="0.060696" iyy="0.87424" iyz="-0.00029206" izz="1.0819" />
        </inertial>
        <visual>
            <origin rpy="0 0 0" xyz="0 0 0" />
            <geometry>
                <mesh filename="package://kr_50_r2500_gazebo/meshes/base_link.STL" />
            </geometry>
            <material name="">
                <color rgba="0.79216 0.81961 0.93333 1" />
            </material>
        </visual>
        <collision>
            <origin rpy="0 0 0" xyz="0 0 0" />
            <geometry>
                <mesh filename="package://kr_50_r2500_gazebo/meshes/base_link.STL" />
            </geometry>
        </collision>
    </link>
    <joint name="world_to_base_link" type="fixed">
        <origin rpy="-1.57079632679 0 0" xyz="0 0 0" />
        <parent link="world" />
        <child link="base_link" />
    </joint>
    <link name="link1">
        <inertial>
            <origin rpy="0 0 0" xyz="0.0600446329714386 0.0116665626627102 0.247062352627269" />
            <mass value="56.0953515273858" />
            <inertia ixx="1.7123503270672" ixy="0.020886843872196" ixz="-0.525246219592262" iyy="2.15349859010488" iyz="-0.031415061955379" izz="1.31690706549715" />
        </inertial>
        <visual>
            <origin rpy="0 0 0" xyz="0 0 0" />
            <geometry>
                <mesh filename="package://kr_50_r2500_gazebo/meshes/link1.STL" />
            </geometry>
            <material name="">
                <color rgba="0.792156862745098 0.819607843137255 0.933333333333333 1" />
            </material>
        </visual>
        <collision>
            <origin rpy="0 0 0" xyz="0 0 0" />
            <geometry>
                <mesh filename="package://kr_50_r2500_gazebo/meshes/link1.STL" />
            </geometry>
        </collision>
    </link>
    <joint name="joint1" type="revolute">
        <origin rpy="1.5708 0.009141 0" xyz="0 -0.17 0" />
        <parent link="base_link" />
        <child link="link1" />
        <axis xyz="0 0 -1" />
        <limit effort="10000" lower="-2.90597" upper="2.90597" velocity="2.74889" />
    </joint>
    <link name="link2">
        <inertial>
            <origin rpy="0 0 0" xyz="0.0040251350126134 -0.177497207044946 0.578963319749875" />
            <mass value="35.5942562362571" />
            <inertia ixx="4.47662495992728" ixy="-0.00203441583192867" ixz="0.0769841500591921" iyy="4.49958249588231" iyz="0.214283202316168" izz="0.238618624180958" />
        </inertial>
        <visual>
            <origin rpy="0 0 0" xyz="0 0 0" />
            <geometry>
                <mesh filename="package://kr_50_r2500_gazebo/meshes/link2.STL" />
            </geometry>
            <material name="">
                <color rgba="0.792156862745098 0.819607843137255 0.933333333333333 1" />
            </material>
        </visual>
        <collision>
            <origin rpy="0 0 0" xyz="0 0 0" />
            <geometry>
                <mesh filename="package://kr_50_r2500_gazebo/meshes/link2.STL" />
            </geometry>
        </collision>
    </link>
    <joint name="joint2" type="revolute">
        <origin rpy="0 1.557055  0" xyz="0.175 -0.074807 0.405" />
        <parent link="link1" />
        <child link="link2" />
        <axis xyz="0 1 0" />
        <limit effort="10000" lower="-2.74889" upper="0.942478" velocity="2.48186" />
    </joint>
    <link name="link3">
        <inertial>
            <origin rpy="0 0 0" xyz="0.0305175734183824 0.097105360534718 0.0162382856824868" />
            <mass value="36.6784876951283" />
            <inertia ixx="0.563908772434098" ixy="0.0648382829251099" ixz="-0.0822356915818992" iyy="0.7868662787778" iyz="0.00379928707270628" izz="1.01511384262152" />
        </inertial>
        <visual>
            <origin rpy="0 0 0" xyz="0 0 0" />
            <geometry>
                <mesh filename="package://kr_50_r2500_gazebo/meshes/link3.STL" />
            </geometry>
            <material name="">
                <color rgba="0.792156862745098 0.819607843137255 0.933333333333333 1" />
            </material>
        </visual>
        <collision>
            <origin rpy="0 0 0" xyz="0 0 0" />
            <geometry>
                <mesh filename="package://kr_50_r2500_gazebo/meshes/link3.STL" />
            </geometry>
        </collision>
    </link>
    <joint name="joint3" type="revolute">
        <origin rpy="0 -1.557055 0" xyz="0 0 1.29" />
        <parent link="link2" />
        <child link="link3" />
        <axis xyz="0 1 0" />
        <limit effort="10000" lower="-1.88496" upper="2.67035" velocity="2.74889" />
    </joint>
    <link name="link4">
        <inertial>
            <origin rpy="0 0 0" xyz="0.400085577392824 0.0280533450779974 -6.01461215805621E-05" />
            <mass value="15.1542881051753" />
            <inertia ixx="0.0701060691297577" ixy="-0.0990093812478981" ixz="0.00018489912158269" iyy="0.729933929975417" iyz="-2.55452640777306E-05" izz="0.748398699396793" />
        </inertial>
        <visual>
            <origin rpy="0 0 0" xyz="0 0 0" />
            <geometry>
                <mesh filename="package://kr_50_r2500_gazebo/meshes/link4.STL" />
            </geometry>
            <material name="">
                <color rgba="0.792156862745098 0.819607843137255 0.933333333333333 1" />
            </material>
        </visual>
        <collision>
            <origin rpy="0 0 0" xyz="0 0 0" />
            <geometry>
                <mesh filename="package://kr_50_r2500_gazebo/meshes/link4.STL" />
            </geometry>
        </collision>
    </link>
    <joint name="joint4" type="revolute">
        <origin rpy="0 0 0" xyz="0.32687 0.074807 0.05" />
        <parent link="link3" />
        <child link="link4" />
        <axis xyz="1 0 0" />
        <limit effort="10000" lower="-2.82743" upper="2.82743" velocity="3.92699" />
    </joint>
    <link name="link5">
        <inertial>
            <origin rpy="0 0 0" xyz="0.0348166227286741 -0.0333672873060013 -7.86869120463773E-05" />
            <mass value="5.17490767884354" />
            <inertia ixx="0.0198943557123769" ixy="-0.00379528838423929" ixz="-3.17734786601442E-05" iyy="0.0325404927644558" iyz="2.0392665049925E-05" izz="0.0334468145607699" />
        </inertial>
        <visual>
            <origin rpy="0 0 0" xyz="0 0 0" />
            <geometry>
                <mesh filename="package://kr_50_r2500_gazebo/meshes/link5.STL" />
            </geometry>
            <material name="">
                <color rgba="0.792156862745098 0.819607843137255 0.933333333333333 1" />
            </material>
        </visual>
        <collision>
            <origin rpy="0 0 0" xyz="0 0 0" />
            <geometry>
                <mesh filename="package://kr_50_r2500_gazebo/meshes/link5.STL" />
            </geometry>
        </collision>
    </link>
    <joint name="joint5" type="revolute">
        <origin rpy="0 -0.0 0" xyz="0.708131634616243 0 0" />
        <parent link="link4" />
        <child link="link5" />
        <axis xyz="0 1 0" />
        <limit effort="10000" lower="-1.9635" upper="1.9635" velocity="3.92699" />
    </joint>
    <link name="link6">
        <inertial>
            <origin rpy="0 0 0" xyz="0.0697663509698883 -2.97159715269453E-06 -4.15148219581329E-05" />
            <mass value="0.362972835401582" />
            <inertia ixx="0.000809216081686161" ixy="9.97029573660496E-10" ixz="2.41841688721677E-07" iyy="0.000440777200154296" iyz="1.15745872636665E-07" izz="0.000441694717362902" />
        </inertial>
        <visual>
            <origin rpy="0 0 0" xyz="0 0 0" />
            <geometry>
                <mesh filename="package://kr_50_r2500_gazebo/meshes/link6.STL" />
            </geometry>
            <material name="">
                <color rgba="0.792156862745098 0.819607843137255 0.933333333333333 1" />
            </material>
        </visual>
        <collision>
            <origin rpy="0 0 0" xyz="0 0 0" />
            <geometry>
                <mesh filename="package://kr_50_r2500_gazebo/meshes/link6.STL" />
            </geometry>
        </collision>
    </link>
    <joint name="joint6" type="revolute">
        <origin rpy="0 0 0" xyz="0.0966663727881543 0 0" />
        <parent link="link5" />
        <child link="link6" />
        <axis xyz="1 0 0" />
        <limit effort="10000" lower="-5.49779" upper="5.49779" velocity="5.65487" />
    </joint>
    <transmission name="tran1">
        <type>transmission_interface/SimpleTransmission</type>
        <joint name="joint1">
            <hardwareInterface>hardware_interface/EffortJointInterface</hardwareInterface>
        </joint>
        <actuator name="motor1">
            <hardwareInterface>hardware_interface/EffortJointInterface</hardwareInterface>
            <mechanicalReduction>1</mechanicalReduction>
        </actuator>
    </transmission>
    <transmission name="tran2">
        <type>transmission_interface/SimpleTransmission</type>
        <joint name="joint2">
            <hardwareInterface>hardware_interface/EffortJointInterface</hardwareInterface>
        </joint>
        <actuator name="motor2">
            <hardwareInterface>hardware_interface/EffortJointInterface</hardwareInterface>
            <mechanicalReduction>1</mechanicalReduction>
        </actuator>
    </transmission>
    <transmission name="tran3">
        <type>transmission_interface/SimpleTransmission</type>
        <joint name="joint3">
            <hardwareInterface>hardware_interface/EffortJointInterface</hardwareInterface>
        </joint>
        <actuator name="motor3">
            <hardwareInterface>hardware_interface/EffortJointInterface</hardwareInterface>
            <mechanicalReduction>1</mechanicalReduction>
        </actuator>
    </transmission>
    <transmission name="tran4">
        <type>transmission_interface/SimpleTransmission</type>
        <joint name="joint4">
            <hardwareInterface>hardware_interface/EffortJointInterface</hardwareInterface>
        </joint>
        <actuator name="motor4">
            <hardwareInterface>hardware_interface/EffortJointInterface</hardwareInterface>
            <mechanicalReduction>1</mechanicalReduction>
        </actuator>
    </transmission>
    <transmission name="tran5">
        <type>transmission_interface/SimpleTransmission</type>
        <joint name="joint5">
            <hardwareInterface>hardware_interface/EffortJointInterface</hardwareInterface>
        </joint>
        <actuator name="motor5">
            <hardwareInterface>hardware_interface/EffortJointInterface</hardwareInterface>
            <mechanicalReduction>1</mechanicalReduction>
        </actuator>
    </transmission>
    <transmission name="tran6">
        <type>transmission_interface/SimpleTransmission</type>
        <joint name="joint6">
            <hardwareInterface>hardware_interface/EffortJointInterface</hardwareInterface>
        </joint>
        <actuator name="motor6">
            <hardwareInterface>hardware_interface/EffortJointInterface</hardwareInterface>
            <mechanicalReduction>1</mechanicalReduction>
        </actuator>
    </transmission>
    <material name="Black">
        <color rgba="0.0 0.0 0.0 1.0" />
    </material>
    <material name="Blue">
        <color rgba="0.0 0.0 0.8 1.0" />
    </material>
    <material name="Green">
        <color rgba="0.0 0.8 0.0 1.0" />
    </material>
    <material name="Grey">
        <color rgba="0.4 0.4 0.4 1.0" />
    </material>
    <material name="Orange">
        <color rgba="1.0 0.4235294117647059 0.0392156862745098 1.0" />
    </material>
    <material name="Brown">
        <color rgba="0.8705882352941177 0.8117647058823529 0.7647058823529411 1.0" />
    </material>
    <material name="Red">
        <color rgba="0.8 0.0 0.0 1.0" />
    </material>
    <material name="White">
        <color rgba="1.0 1.0 1.0 1.0" />
    </material>
    <material name="LightGrey">
        <color rgba="0.7 0.7 0.7 1" />
    </material>
    <material name="DarkGray">
        <color rgba="0.2 0.2 0.2 1" />
    </material>
    <material name="DarkDarkGray">
        <color rgba="0.1 0.1 0.1 1" />
    </material>
    <link name="gripper_root" />
    <joint name="gripper_visual_palm_joint" type="fixed">
        <origin rpy="0 0 0.7853981633974483" xyz="0 0 0.02705" />
        <parent link="gripper_root" />
        <child link="gripper_visual_palm" />
    </joint>
    <link name="gripper_visual_palm">
        <inertial>
            <origin rpy="0 0 0" xyz="0 0 0" />
            <mass value="1" />
            <inertia ixx="0.01" ixy="0" ixz="0" iyy="0.01" iyz="0" izz="0.01" />
        </inertial>
        <visual>
            <origin rpy="0 0 0" xyz="0 0 0" />
            <geometry>
                <mesh filename="package://victor_description/meshes/robotiq_3finger/palm_visual.stl" />
            </geometry>
            <material name="DarkGray" />
        </visual>
        <collision>
            <origin rpy="0 0 0" xyz="0 0 0" />
            <geometry>
                <mesh filename="package://victor_description/meshes/robotiq_3finger/palm_collision.stl" />
            </geometry>
            <material name="DarkGray" />
        </collision>
    </link>
    <!-- Palm surface aligned with the gripper axis -->
    <joint name="gripper_visual_palm_surface_joint" type="fixed">
        <parent link="gripper_visual_palm" />
        <child link="gripper_visual_palm_surface" />
        <origin rpy="0 0 0" xyz="0 0 0.092075" />
    </joint>
    <link name="gripper_visual_palm_surface" />
    <!-- Kuka internal frame has been changed to match our external usage, so identity transform -->
    <joint name="gripper_visual_palm_surface_kuka_joint" type="fixed">
        <parent link="gripper_visual_palm_surface" />
        <child link="gripper_visual_palm_surface_kuka" />
        <origin rpy="0 0 0" xyz="0 0 0" />
    </joint>
    <link name="gripper_visual_palm_surface_kuka" />
    <!-- Finger A -->
    <joint name="gripper_visual_fingerA_knuckle" type="fixed">
        <origin rpy="0 0 0" xyz="0.02225040 0 0.06111875" />
        <parent link="gripper_visual_palm" />
        <child link="gripper_visual_fingerA_base" />
    </joint>
    <link name="gripper_visual_fingerA_base">
        <inertial>
            <origin rpy="0 0 0" xyz="0 0 0" />
            <mass value="1" />
            <inertia ixx="0.01" ixy="0" ixz="0" iyy="0.01" iyz="0" izz="0.01" />
        </inertial>
        <visual>
            <origin rpy="0 0 0" xyz="0 0 0" />
            <geometry>
                <mesh filename="package://victor_description/meshes/robotiq_3finger/finger_link1_base_visual.stl" />
            </geometry>
            <material name="DarkGray" />
        </visual>
        <collision>
            <origin rpy="0 0 0" xyz="0 0 0" />
            <geometry>
                <mesh filename="package://victor_description/meshes/robotiq_3finger/finger_link1_base_visual.stl" />
            </geometry>
            <material name="DarkGray" />
        </collision>
    </link>
    <!-- Joint 2 (base-prox) -->
    <joint name="gripper_visual_fingerA_joint_2" type="revolute">
        <parent link="gripper_visual_fingerA_base" />
        <child link="gripper_visual_fingerA_prox" />
        <origin rpy="0 0.6108652381980153 0" xyz="0.02225000 0 0.02151380" />
        <axis xyz="0 -1 0" />
        <limit effort="300" lower="0" upper="1.2217304763960307" velocity="10" />
        <safety_controller k_position="100" k_velocity="2" soft_lower_limit="-0.6108652381980153" soft_upper_limit="0.6108652381980153" />
        <dynamics damping="0.5" />
    </joint>
    <link name="gripper_visual_fingerA_prox">
        <inertial>
            <origin rpy="0 0 0" xyz="0 0 0" />
            <mass value="1" />
            <inertia ixx="0.01" ixy="0" ixz="0" iyy="0.01" iyz="0" izz="0.01" />
        </inertial>
        <visual>
            <origin rpy="0 0 0" xyz="0 0 0" />
            <geometry>
                <mesh filename="package://victor_description/meshes/robotiq_3finger/finger_link2_prox_visual.stl" />
            </geometry>
            <material name="DarkGray" />
        </visual>
        <collision>
            <origin rpy="0 0 0" xyz="0 0 0" />
            <geometry>
                <mesh filename="package://victor_description/meshes/robotiq_3finger/finger_link2_prox_collision.stl" />
            </geometry>
            <material name="DarkGray" />
        </collision>
    </link>
    <!-- Joint 3 (prox-med) -->
    <joint name="gripper_visual_fingerA_joint_3" type="revolute">
        <parent link="gripper_visual_fingerA_prox" />
        <child link="gripper_visual_fingerA_med" />
        <origin rpy="0 0 0" xyz="0 0 0.05715000" />
        <axis xyz="0 -1 0" />
        <limit effort="300" lower="-1" upper="1" velocity="10" />
        <safety_controller k_position="100" k_velocity="2" soft_lower_limit="0.0" soft_upper_limit="1.5707963267948966" />
        <dynamics damping="0.5" />
    </joint>
    <link name="gripper_visual_fingerA_med">
        <inertial>
            <origin rpy="0 0 0" xyz="0 0 0" />
            <mass value="1" />
            <inertia ixx="0.01" ixy="0" ixz="0" iyy="0.01" iyz="0" izz="0.01" />
        </inertial>
        <visual>
            <origin rpy="0 0 0" xyz="0 0 0" />
            <geometry>
                <mesh filename="package://victor_description/meshes/robotiq_3finger/finger_link3_med_visual.stl" />
            </geometry>
            <material name="DarkGray" />
        </visual>
        <collision>
            <origin rpy="0 0 0" xyz="0 0 0" />
            <geometry>
                <mesh filename="package://victor_description/meshes/robotiq_3finger/finger_link3_med_collision.stl" />
            </geometry>
            <material name="DarkGray" />
        </collision>
    </link>
    <!-- Joint 4 (med-dist) -->
    <joint name="gripper_visual_fingerA_joint_4" type="revolute">
        <parent link="gripper_visual_fingerA_med" />
        <child link="gripper_visual_fingerA_dist" />
        <origin rpy="0 -0.4363323129985824 0" xyz="0 0 0.03810000" />
        <axis xyz="0 -1 0" />
        <limit effort="300" lower="-1" upper="1" velocity="10" />
        <safety_controller k_position="100" k_velocity="2" soft_lower_limit="-0.4363323129985824" soft_upper_limit="1.2740903539558606" />
        <dynamics damping="0.5" />
    </joint>
    <link name="gripper_visual_fingerA_dist">
        <inertial>
            <origin rpy="0 0 0" xyz="0 0 0" />
            <mass value="1" />
            <inertia ixx="0.01" ixy="0" ixz="0" iyy="0.01" iyz="0" izz="0.01" />
        </inertial>
        <visual>
            <origin rpy="0 0 0" xyz="0 0 0" />
            <geometry>
                <mesh filename="package://victor_description/meshes/robotiq_3finger/finger_link4_dist_visual.stl" />
            </geometry>
            <material name="DarkGray" />
        </visual>
        <collision>
            <origin rpy="0 0 0" xyz="0 0 0" />
            <geometry>
                <mesh filename="package://victor_description/meshes/robotiq_3finger/finger_link4_dist_collision.stl" />
            </geometry>
            <material name="DarkGray" />
        </collision>
    </link>
    <!-- Finger B -->
    <joint name="gripper_visual_fingerB_knuckle" type="revolute">
        <origin rpy="0 0 3.141592653589793" xyz="-0.02230120 0.03651250 0.06111875" />
        <parent link="gripper_visual_palm" />
        <child link="gripper_visual_fingerB_base" />
        <axis xyz="-1 0 0" />
        <limit effort="300" lower="-0.2792526803190927" upper="0.17453292519943295" velocity="10" />
        <safety_controller k_position="100" k_velocity="2" soft_lower_limit="-0.24434609527920614" soft_upper_limit="0.13962634015954636" />
        <dynamics damping="0.5" />
    </joint>
    <link name="gripper_visual_fingerB_base">
        <inertial>
            <origin rpy="0 0 0" xyz="0 0 0" />
            <mass value="1" />
            <inertia ixx="0.01" ixy="0" ixz="0" iyy="0.01" iyz="0" izz="0.01" />
        </inertial>
        <visual>
            <origin rpy="0 0 0" xyz="0 0 0" />
            <geometry>
                <mesh filename="package://victor_description/meshes/robotiq_3finger/finger_link1_base_visual.stl" />
            </geometry>
            <material name="DarkGray" />
        </visual>
        <collision>
            <origin rpy="0 0 0" xyz="0 0 0" />
            <geometry>
                <mesh filename="package://victor_description/meshes/robotiq_3finger/finger_link1_base_visual.stl" />
            </geometry>
            <material name="DarkGray" />
        </collision>
    </link>
    <!-- Joint 2 (base-prox) -->
    <joint name="gripper_visual_fingerB_joint_2" type="revolute">
        <parent link="gripper_visual_fingerB_base" />
        <child link="gripper_visual_fingerB_prox" />
        <origin rpy="0 0.6108652381980153 0" xyz="0.02225000 0 0.02151380" />
        <axis xyz="0 -1 0" />
        <limit effort="300" lower="0" upper="1.2217304763960307" velocity="10" />
        <safety_controller k_position="100" k_velocity="2" soft_lower_limit="-0.6108652381980153" soft_upper_limit="0.6108652381980153" />
        <dynamics damping="0.5" />
    </joint>
    <link name="gripper_visual_fingerB_prox">
        <inertial>
            <origin rpy="0 0 0" xyz="0 0 0" />
            <mass value="1" />
            <inertia ixx="0.01" ixy="0" ixz="0" iyy="0.01" iyz="0" izz="0.01" />
        </inertial>
        <visual>
            <origin rpy="0 0 0" xyz="0 0 0" />
            <geometry>
                <mesh filename="package://victor_description/meshes/robotiq_3finger/finger_link2_prox_visual.stl" />
            </geometry>
            <material name="DarkGray" />
        </visual>
        <collision>
            <origin rpy="0 0 0" xyz="0 0 0" />
            <geometry>
                <mesh filename="package://victor_description/meshes/robotiq_3finger/finger_link2_prox_collision.stl" />
            </geometry>
            <material name="DarkGray" />
        </collision>
    </link>
    <!-- Joint 3 (prox-med) -->
    <joint name="gripper_visual_fingerB_joint_3" type="revolute">
        <parent link="gripper_visual_fingerB_prox" />
        <child link="gripper_visual_fingerB_med" />
        <origin rpy="0 0 0" xyz="0 0 0.05715000" />
        <axis xyz="0 -1 0" />
        <limit effort="300" lower="-1" upper="1" velocity="10" />
        <safety_controller k_position="100" k_velocity="2" soft_lower_limit="0.0" soft_upper_limit="1.5707963267948966" />
        <dynamics damping="0.5" />
    </joint>
    <link name="gripper_visual_fingerB_med">
        <inertial>
            <origin rpy="0 0 0" xyz="0 0 0" />
            <mass value="1" />
            <inertia ixx="0.01" ixy="0" ixz="0" iyy="0.01" iyz="0" izz="0.01" />
        </inertial>
        <visual>
            <origin rpy="0 0 0" xyz="0 0 0" />
            <geometry>
                <mesh filename="package://victor_description/meshes/robotiq_3finger/finger_link3_med_visual.stl" />
            </geometry>
            <material name="DarkGray" />
        </visual>
        <collision>
            <origin rpy="0 0 0" xyz="0 0 0" />
            <geometry>
                <mesh filename="package://victor_description/meshes/robotiq_3finger/finger_link3_med_collision.stl" />
            </geometry>
            <material name="DarkGray" />
        </collision>
    </link>
    <!-- Joint 4 (med-dist) -->
    <joint name="gripper_visual_fingerB_joint_4" type="revolute">
        <parent link="gripper_visual_fingerB_med" />
        <child link="gripper_visual_fingerB_dist" />
        <origin rpy="0 -0.4363323129985824 0" xyz="0 0 0.03810000" />
        <axis xyz="0 -1 0" />
        <limit effort="300" lower="-1" upper="1" velocity="10" />
        <safety_controller k_position="100" k_velocity="2" soft_lower_limit="-0.4363323129985824" soft_upper_limit="1.2740903539558606" />
        <dynamics damping="0.5" />
    </joint>
    <link name="gripper_visual_fingerB_dist">
        <inertial>
            <origin rpy="0 0 0" xyz="0 0 0" />
            <mass value="1" />
            <inertia ixx="0.01" ixy="0" ixz="0" iyy="0.01" iyz="0" izz="0.01" />
        </inertial>
        <visual>
            <origin rpy="0 0 0" xyz="0 0 0" />
            <geometry>
                <mesh filename="package://victor_description/meshes/robotiq_3finger/finger_link4_dist_visual.stl" />
            </geometry>
            <material name="DarkGray" />
        </visual>
        <collision>
            <origin rpy="0 0 0" xyz="0 0 0" />
            <geometry>
                <mesh filename="package://victor_description/meshes/robotiq_3finger/finger_link4_dist_collision.stl" />
            </geometry>
            <material name="DarkGray" />
        </collision>
    </link>
    <!-- Finger C -->
    <joint name="gripper_visual_fingerC_knuckle" type="revolute">
        <origin rpy="0 0 3.141592653589793" xyz="-0.02230120 -0.03651250 0.06111875" />
        <parent link="gripper_visual_palm" />
        <child link="gripper_visual_fingerC_base" />
        <axis xyz="1 0 0" />
        <limit effort="300" lower="-0.2792526803190927" upper="0.17453292519943295" velocity="10" />
        <safety_controller k_position="100" k_velocity="2" soft_lower_limit="-0.24434609527920614" soft_upper_limit="0.13962634015954636" />
        <dynamics damping="0.5" />
    </joint>
    <link name="gripper_visual_fingerC_base">
        <inertial>
            <origin rpy="0 0 0" xyz="0 0 0" />
            <mass value="1" />
            <inertia ixx="0.01" ixy="0" ixz="0" iyy="0.01" iyz="0" izz="0.01" />
        </inertial>
        <visual>
            <origin rpy="0 0 0" xyz="0 0 0" />
            <geometry>
                <mesh filename="package://victor_description/meshes/robotiq_3finger/finger_link1_base_visual.stl" />
            </geometry>
            <material name="DarkGray" />
        </visual>
        <collision>
            <origin rpy="0 0 0" xyz="0 0 0" />
            <geometry>
                <mesh filename="package://victor_description/meshes/robotiq_3finger/finger_link1_base_visual.stl" />
            </geometry>
            <material name="DarkGray" />
        </collision>
    </link>
    <!-- Joint 2 (base-prox) -->
    <joint name="gripper_visual_fingerC_joint_2" type="revolute">
        <parent link="gripper_visual_fingerC_base" />
        <child link="gripper_visual_fingerC_prox" />
        <origin rpy="0 0.6108652381980153 0" xyz="0.02225000 0 0.02151380" />
        <axis xyz="0 -1 0" />
        <limit effort="300" lower="0" upper="1.2217304763960307" velocity="10" />
        <safety_controller k_position="100" k_velocity="2" soft_lower_limit="-0.6108652381980153" soft_upper_limit="0.6108652381980153" />
        <dynamics damping="0.5" />
    </joint>
    <link name="gripper_visual_fingerC_prox">
        <inertial>
            <origin rpy="0 0 0" xyz="0 0 0" />
            <mass value="1" />
            <inertia ixx="0.01" ixy="0" ixz="0" iyy="0.01" iyz="0" izz="0.01" />
        </inertial>
        <visual>
            <origin rpy="0 0 0" xyz="0 0 0" />
            <geometry>
                <mesh filename="package://victor_description/meshes/robotiq_3finger/finger_link2_prox_visual.stl" />
            </geometry>
            <material name="DarkGray" />
        </visual>
        <collision>
            <origin rpy="0 0 0" xyz="0 0 0" />
            <geometry>
                <mesh filename="package://victor_description/meshes/robotiq_3finger/finger_link2_prox_collision.stl" />
            </geometry>
            <material name="DarkGray" />
        </collision>
    </link>
    <!-- Joint 3 (prox-med) -->
    <joint name="gripper_visual_fingerC_joint_3" type="revolute">
        <parent link="gripper_visual_fingerC_prox" />
        <child link="gripper_visual_fingerC_med" />
        <origin rpy="0 0 0" xyz="0 0 0.05715000" />
        <axis xyz="0 -1 0" />
        <limit effort="300" lower="-1" upper="1" velocity="10" />
        <safety_controller k_position="100" k_velocity="2" soft_lower_limit="0.0" soft_upper_limit="1.5707963267948966" />
        <dynamics damping="0.5" />
    </joint>
    <link name="gripper_visual_fingerC_med">
        <inertial>
            <origin rpy="0 0 0" xyz="0 0 0" />
            <mass value="1" />
            <inertia ixx="0.01" ixy="0" ixz="0" iyy="0.01" iyz="0" izz="0.01" />
        </inertial>
        <visual>
            <origin rpy="0 0 0" xyz="0 0 0" />
            <geometry>
                <mesh filename="package://victor_description/meshes/robotiq_3finger/finger_link3_med_visual.stl" />
            </geometry>
            <material name="DarkGray" />
        </visual>
        <collision>
            <origin rpy="0 0 0" xyz="0 0 0" />
            <geometry>
                <mesh filename="package://victor_description/meshes/robotiq_3finger/finger_link3_med_collision.stl" />
            </geometry>
            <material name="DarkGray" />
        </collision>
    </link>
    <!-- Joint 4 (med-dist) -->
    <joint name="gripper_visual_fingerC_joint_4" type="revolute">
        <parent link="gripper_visual_fingerC_med" />
        <child link="gripper_visual_fingerC_dist" />
        <origin rpy="0 -0.4363323129985824 0" xyz="0 0 0.03810000" />
        <axis xyz="0 -1 0" />
        <limit effort="300" lower="-1" upper="1" velocity="10" />
        <safety_controller k_position="100" k_velocity="2" soft_lower_limit="-0.4363323129985824" soft_upper_limit="1.2740903539558606" />
        <dynamics damping="0.5" />
    </joint>
    <link name="gripper_visual_fingerC_dist">
        <inertial>
            <origin rpy="0 0 0" xyz="0 0 0" />
            <mass value="1" />
            <inertia ixx="0.01" ixy="0" ixz="0" iyy="0.01" iyz="0" izz="0.01" />
        </inertial>
        <visual>
            <origin rpy="0 0 0" xyz="0 0 0" />
            <geometry>
                <mesh filename="package://victor_description/meshes/robotiq_3finger/finger_link4_dist_visual.stl" />
            </geometry>
            <material name="DarkGray" />
        </visual>
        <collision>
            <origin rpy="0 0 0" xyz="0 0 0" />
            <geometry>
                <mesh filename="package://victor_description/meshes/robotiq_3finger/finger_link4_dist_collision.stl" />
            </geometry>
            <material name="DarkGray" />
        </collision>
    </link>
    <joint name="gripper_fixed" type="fixed">
        <origin rpy="0 1.57079632679 0" xyz="0.06 0 0" />
        <parent link="link6" />
        <child link="gripper_root" />
    </joint>
    <gazebo>
        <plugin filename="libgazebo_ros_control.so" name="gazebo_ros_control">
            <robotNamespace>/kr_50_r2500</robotNamespace>
            <robotSimType>gazebo_ros_control/DefaultRobotHWSim</robotSimType>
        </plugin>
    </gazebo>
    <gazebo reference="gripper_fixed">
        <provideFeedback>true</provideFeedback>
        <disableFixedJointLumping>true</disableFixedJointLumping>
        <preserveFixedJoint>true</preserveFixedJoint>
    </gazebo>
    <gazebo>
        <plugin filename="libgazebo_ros_ft_sensor.so" name="ft_sensor">
            <updateRate>100.0</updateRate>
            <topicName>gripper/wrench</topicName>
            <jointName>gripper_fixed</jointName>
        </plugin>
    </gazebo>
    <!-- <xacro:include filename="$(find kr_50_r2500_gazebo)/urdf/kr_50_r2500_cell.xacro" /> -->
    <transmission name="trans_gripper_visual_fingerA_joint_2">
        <type>transmission_interface/SimpleTransmission</type>
        <joint name="gripper_visual_fingerA_joint_2">
            <hardwareInterface>hardware_interface/EffortJointInterface</hardwareInterface>
        </joint>
        <actuator name="gripper_visual_fingerA_joint_2_motor">
            <hardwareInterface>hardware_interface/EffortJointInterface</hardwareInterface>
            <mechanicalReduction>1</mechanicalReduction>
        </actuator>
    </transmission>
    <transmission name="trans_gripper_visual_fingerA_joint_3">
        <type>transmission_interface/SimpleTransmission</type>
        <joint name="gripper_visual_fingerA_joint_3">
            <hardwareInterface>hardware_interface/EffortJointInterface</hardwareInterface>
        </joint>
        <actuator name="gripper_visual_fingerA_joint_3_motor">
            <hardwareInterface>hardware_interface/EffortJointInterface</hardwareInterface>
            <mechanicalReduction>1</mechanicalReduction>
        </actuator>
    </transmission>
    <transmission name="trans_gripper_visual_fingerA_joint_4">
        <type>transmission_interface/SimpleTransmission</type>
        <joint name="gripper_visual_fingerA_joint_4">
            <hardwareInterface>hardware_interface/EffortJointInterface</hardwareInterface>
        </joint>
        <actuator name="gripper_visual_fingerA_joint_4_motor">
            <hardwareInterface>hardware_interface/EffortJointInterface</hardwareInterface>
            <mechanicalReduction>1</mechanicalReduction>
        </actuator>
    </transmission>
    <transmission name="trans_gripper_visual_fingerB_knuckle">
        <type>transmission_interface/SimpleTransmission</type>
        <joint name="gripper_visual_fingerB_knuckle">
            <hardwareInterface>hardware_interface/EffortJointInterface</hardwareInterface>
        </joint>
        <actuator name="gripper_visual_fingerB_knuckle_motor">
            <hardwareInterface>hardware_interface/EffortJointInterface</hardwareInterface>
            <mechanicalReduction>1</mechanicalReduction>
        </actuator>
    </transmission>
    <transmission name="trans_gripper_visual_fingerB_joint_2">
        <type>transmission_interface/SimpleTransmission</type>
        <joint name="gripper_visual_fingerB_joint_2">
            <hardwareInterface>hardware_interface/EffortJointInterface</hardwareInterface>
        </joint>
        <actuator name="gripper_visual_fingerB_joint_2_motor">
            <hardwareInterface>hardware_interface/EffortJointInterface</hardwareInterface>
            <mechanicalReduction>1</mechanicalReduction>
        </actuator>
    </transmission>
    <transmission name="trans_gripper_visual_fingerB_joint_3">
        <type>transmission_interface/SimpleTransmission</type>
        <joint name="gripper_visual_fingerB_joint_3">
            <hardwareInterface>hardware_interface/EffortJointInterface</hardwareInterface>
        </joint>
        <actuator name="gripper_visual_fingerB_joint_3_motor">
            <hardwareInterface>hardware_interface/EffortJointInterface</hardwareInterface>
            <mechanicalReduction>1</mechanicalReduction>
        </actuator>
    </transmission>
    <transmission name="trans_gripper_visual_fingerB_joint_4">
        <type>transmission_interface/SimpleTransmission</type>
        <joint name="gripper_visual_fingerB_joint_4">
            <hardwareInterface>hardware_interface/EffortJointInterface</hardwareInterface>
        </joint>
        <actuator name="gripper_visual_fingerB_joint_4_motor">
            <hardwareInterface>hardware_interface/EffortJointInterface</hardwareInterface>
            <mechanicalReduction>1</mechanicalReduction>
        </actuator>
    </transmission>
    <transmission name="trans_gripper_visual_fingerC_knuckle">
        <type>transmission_interface/SimpleTransmission</type>
        <joint name="gripper_visual_fingerC_knuckle">
            <hardwareInterface>hardware_interface/EffortJointInterface</hardwareInterface>
        </joint>
        <actuator name="gripper_visual_fingerC_knuckle_motor">
            <hardwareInterface>hardware_interface/EffortJointInterface</hardwareInterface>
            <mechanicalReduction>1</mechanicalReduction>
        </actuator>
    </transmission>
    <transmission name="trans_gripper_visual_fingerC_joint_2">
        <type>transmission_interface/SimpleTransmission</type>
        <joint name="gripper_visual_fingerC_joint_2">
            <hardwareInterface>hardware_interface/EffortJointInterface</hardwareInterface>
        </joint>
        <actuator name="gripper_visual_fingerC_joint_2_motor">
            <hardwareInterface>hardware_interface/EffortJointInterface</hardwareInterface>
            <mechanicalReduction>1</mechanicalReduction>
        </actuator>
    </transmission>
    <transmission name="trans_gripper_visual_fingerC_joint_3">
        <type>transmission_interface/SimpleTransmission</type>
        <joint name="gripper_visual_fingerC_joint_3">
            <hardwareInterface>hardware_interface/EffortJointInterface</hardwareInterface>
        </joint>
        <actuator name="gripper_visual_fingerC_joint_3_motor">
            <hardwareInterface>hardware_interface/EffortJointInterface</hardwareInterface>
            <mechanicalReduction>1</mechanicalReduction>
        </actuator>
    </transmission>
    <transmission name="trans_gripper_visual_fingerC_joint_4">
        <type>transmission_interface/SimpleTransmission</type>
        <joint name="gripper_visual_fingerC_joint_4">
            <hardwareInterface>hardware_interface/EffortJointInterface</hardwareInterface>
        </joint>
        <actuator name="gripper_visual_fingerC_joint_4_motor">
            <hardwareInterface>hardware_interface/EffortJointInterface</hardwareInterface>
            <mechanicalReduction>1</mechanicalReduction>
        </actuator>
    </transmission>
</robot>

